Workbook

Sheet Historias de Usuario
B1: Desarrollo ágil: Historias de usuario y criterios de aceptación
B2: Quality360 · Dashboard de certificación QA de historias de usuario · Capstone DuocUC — Grupo 8
B3: Leyenda: ID con prefijo F = HDU de Frontend · B = HDU de Backend. Cada HDU se desglosa en escenarios (criterios de aceptación) con formato Contexto → Evento → Resultado.
C4: Enunciado de la historia | G4: Criterios de aceptación
B5: Identificador (ID) de la historia | C5: Rol | D5: Característica / Funcionalidad | E5: Razón / Resultado | F5: Número (#) de escenario | G5: Criterio de aceptación (Título) | H5: Contexto | I5: Evento | J5: Resultado / Comportamiento esperado | K5: Epica
B6: ÉPICA 1 — ACCESO, PORTALES Y ORGANIZACIÓN QA · Autenticación, autorización por rol y ámbito, portales de inicio y administración de usuarios, roles y supervisión.
B7: E1-F01 | C7: Usuario de Quality360 | D7: Como Usuario de Quality360, quiero ingresar al portal de inicio de sesión e introducir mis credenciales | E7: Para acceder a la plataforma de forma segura | F7: 1 | G7: Formulario de ingreso | H7: El usuario accede a la pantalla de inicio de sesión. | I7: Visualiza el formulario. | J7: Se muestran los campos de correo y contraseña, con opción de mostrar u ocultar la contraseña. | K7: 1
F8: 2 | G8: Campos obligatorios | H8: El usuario deja el correo o la contraseña en blanco. | I8: Presiona Ingresar. | J8: El sistema valida los campos obligatorios y marca los que faltan sin enviar la solicitud.
F9: 3 | G9: Credenciales incorrectas | H9: El usuario ingresa credenciales válidas en formato pero incorrectas. | I9: Presiona Ingresar. | J9: Se indica que el ingreso está en proceso y luego se presenta un mensaje genérico de credenciales incorrectas, sin revelar si el correo existe.
B10: E1-F02 | C10: Quality Engineer (QE) | D10: Como Quality Engineer (QE), quiero ingresar al portal del QE después de iniciar sesión | E10: Para acceder a las funciones de supervisión de mi equipo | F10: 1 | G10: Redirección al portal QE | H10: El usuario tiene rol QE y credenciales válidas. | I10: Inicia sesión. | J10: Es dirigido a su portal, que muestra su identidad y la navegación de supervisión. | K10: 1
F11: 2 | G11: Acceso a ruta de otro rol | H11: El QE está autenticado. | I11: Intenta abrir una ruta administrativa o de analista. | J11: Se presenta acceso denegado o se redirige al portal autorizado.
F12: 3 | G12: Navegación disponible | H12: El QE está en su portal. | I12: Revisa el menú. | J12: Solo aparecen opciones de supervisión (equipo, historias supervisadas, perfil, cerrar sesión).
B13: E1-F03 | C13: Quality Engineer (QE) | D13: Como Quality Engineer (QE), quiero ver mi panel de inicio con un resumen de mis analistas e historias bajo supervisión | E13: Para identificar mi ámbito de trabajo y acceder a su seguimiento | F13: 1 | G13: Resumen con datos | H13: El QE tiene analistas e historias asignadas. | I13: Ingresa al panel de inicio. | J13: Se muestra la cantidad de analistas supervisados y de HDU bajo supervisión, con acceso a ambos listados. | K13: 1
F14: 2 | G14: Sin datos | H14: El QE no tiene analistas ni historias asignadas. | I14: Ingresa al panel de inicio. | J14: Se informa explícitamente la ausencia de datos, sin mostrar cifras ficticias.
F15: 3 | G15: Error de consulta | H15: El servicio de resumen no responde. | I15: Ingresa al panel de inicio. | J15: Se diferencia el estado de error del estado de carga y de la ausencia de datos, con opción de reintentar.
B16: E1-F04 | C16: Quality Engineer (QE) | D16: Como Quality Engineer (QE), quiero consultar el listado de analistas QA que superviso | E16: Para reconocer los integrantes de mi equipo | F16: 1 | G16: Listado vigente | H16: El QE tiene relaciones de supervisión vigentes. | I16: Abre la sección de analistas. | J16: Se muestran únicamente los analistas con supervisión vigente, identificados por nombre y correo. | K16: 1
F17: 2 | G17: Relaciones finalizadas | H17: Un analista fue reasignado a otro QE. | I17: Abre la sección de analistas. | J17: El analista reasignado no aparece en el listado.
F18: 3 | G18: Sin analistas | H18: El QE no tiene analistas asignados. | I18: Abre la sección de analistas. | J18: Se informa que no hay analistas asignados.
B19: E1-F05 | C19: Analista QA | D19: Como Analista QA, quiero ingresar al portal del QA después de iniciar sesión | E19: Para acceder a las funciones correspondientes a mi trabajo de certificación | F19: 1 | G19: Redirección al portal QA | H19: El usuario tiene rol Analista QA. | I19: Inicia sesión. | J19: Es dirigido a su portal, con su identidad y la navegación correspondiente. | K19: 1
F20: 2 | G20: Sin funciones administrativas | H20: El analista está en su portal. | I20: Revisa el menú y las rutas. | J20: No se presentan funciones administrativas ni de supervisión.
F21: 3 | G21: Ruta no autorizada | H21: El analista está autenticado. | I21: Intenta abrir una ruta de QE o Administrador. | J21: Se presenta acceso denegado o se redirige a su portal.
B22: E1-F06 | C22: Analista QA | D22: Como Analista QA, quiero ver mi panel de inicio con mi QE supervisor y un resumen de mis historias asignadas | E22: Para identificar mis responsabilidades y a quién acudir ante un impedimento | F22: 1 | G22: Panel con supervisor e historias | H22: El analista tiene QE vigente e historias asignadas. | I22: Ingresa al panel de inicio. | J22: Se muestra el nombre del QE supervisor y la cantidad de HDU asignadas, con acceso a sus historias. | K22: 1
F23: 2 | G23: Sin supervisor | H23: El analista no tiene QE vigente. | I23: Ingresa al panel de inicio. | J23: Se informa que no tiene supervisor asignado.
F24: 3 | G24: Conteo no disponible | H24: La capacidad de HDU (E2) aún no está habilitada. | I24: Ingresa al panel de inicio. | J24: El portal indica que el conteo de historias todavía no está disponible.
B25: E1-F07 | C25: Administrador (Líder QA) | D25: Como Administrador, quiero ingresar al portal de administración después de iniciar sesión | E25: Para acceder a la configuración de usuarios y organización QA | F25: 1 | G25: Redirección al portal administrativo | H25: El usuario tiene rol Administrador. | I25: Inicia sesión. | J25: Es dirigido a su portal con los accesos administrativos habilitados. | K25: 1
F26: 2 | G26: Accesos habilitados | H26: El Administrador está en su portal. | I26: Revisa la navegación. | J26: Se presentan accesos a usuarios, roles y supervisión.
F27: 3 | G27: Sesión expirada | H27: La sesión del Administrador expiró. | I27: Intenta abrir el portal. | J27: Se le solicita iniciar sesión nuevamente.
B28: E1-F08 | C28: Administrador (Líder QA) | D28: Como Administrador, quiero ver mi panel de inicio con accesos a usuarios, roles y relaciones de supervisión | E28: Para administrar la estructura de acceso de la plataforma | F28: 1 | G28: Panel administrativo | H28: El Administrador ingresa a su panel. | I28: Visualiza el panel. | J28: Se muestran accesos a gestión de usuarios, roles y supervisión. | K28: 1
F29: 2 | G29: Error de carga | H29: El servicio administrativo no responde. | I29: Ingresa al panel. | J29: Se informa el error de carga sin mostrar cifras ficticias.
F30: 3 | G30: Navegación directa | H30: El Administrador está en el panel. | I30: Selecciona un acceso. | J30: Se abre la pantalla correspondiente.
B31: E1-F09 | C31: Administrador (Líder QA) | D31: Como Administrador, quiero utilizar una pantalla para registrar usuarios, actualizar sus datos, asignar su rol y activar o desactivar su acceso | E31: Para mantener vigente el acceso de los participantes | F31: 1 | G31: Listar y buscar | H31: Existen usuarios registrados. | I31: Abre la pantalla de usuarios y busca por nombre o correo. | J31: Se listan los usuarios y el buscador filtra los resultados. | K31: 1
F32: 2 | G32: Validación de datos | H32: El Administrador registra un usuario con datos incompletos. | I32: Guarda el formulario. | J32: Se validan los datos obligatorios y se indican los errores.
F33: 3 | G33: Confirmación de cambios sensibles | H33: El Administrador desactiva un usuario o cambia su rol. | I33: Confirma la operación. | J33: Se solicita confirmación previa y se muestra el resultado de la operación.
B34: E1-F10 | C34: Administrador (Líder QA) | D34: Como Administrador, quiero utilizar una pantalla para asignar o cambiar el QE supervisor de un analista QA | E34: Para mantener actualizada la organización del equipo | F34: 1 | G34: Selección de analista y QE | H34: Existen analistas y QE activos. | I34: Selecciona un analista y un QE. | J34: Se muestra la relación vigente del analista antes de confirmar. | K34: 1
F35: 2 | G35: Motivo del cambio | H35: El analista ya tiene un QE vigente. | I35: Asigna un nuevo QE. | J35: Se solicita el motivo del cambio antes de guardar.
F36: 3 | G36: Historial de supervisión | H36: El analista ha tenido varios supervisores. | I36: Consulta el historial. | J36: Se muestran las relaciones anteriores con fechas y motivos.
B37: E1-F11 | C37: Usuario autenticado | D37: Como Usuario autenticado, quiero consultar mi nombre, correo y rol en la plataforma | E37: Para verificar con qué identidad y permisos estoy trabajando | F37: 1 | G37: Datos del perfil | H37: El usuario está autenticado. | I37: Abre su perfil. | J37: Se muestran su nombre, correo y rol. | K37: 1
F38: 2 | G38: Rol de solo lectura | H38: El usuario está en su perfil. | I38: Intenta modificar el rol. | J38: El rol no es editable desde el perfil personal.
F39: 3 | G39: Datos actualizados | H39: El Administrador cambió el rol del usuario. | I39: El usuario vuelve a abrir su perfil. | J39: Se refleja el rol vigente.
B40: E1-F12 | C40: Usuario autenticado | D40: Como Usuario autenticado, quiero cerrar sesión desde mi portal | E40: Para finalizar mi acceso a la plataforma | F40: 1 | G40: Opción visible | H40: El usuario está en su portal. | I40: Busca la opción de salir. | J40: La opción de cerrar sesión es visible desde cualquier pantalla. | K40: 1
...

Sheet Épicas
B1: Quality360 · Épicas del producto
B2: Resumen de épicas y cantidad de HDU. Los conteos se calculan desde la hoja Historias de Usuario.
B4: Épica | C4: Nombre | D4: Descripción | E4: HDU Frontend | F4: HDU Backend | G4: Total HDU
B5: 1 | C5: Acceso, portales y organización QA | D5: Autenticación, autorización por rol y ámbito, portales de inicio y administración de usuarios, roles y supervisión. | E5: =COUNTIF('Historias de Usuario'!$B:$B,"E1-F*") -> 13 | F5: =COUNTIF('Historias de Usuario'!$B:$B,"E1-B*") -> 13 | G5: =E5+F5 -> 26
B6: 2 | C6: Gestión de historias de usuario (HDU) | D6: Registro, asignación, estados y consulta de las HDU bajo certificación, organizadas por célula y sprint. | E6: =COUNTIF('Historias de Usuario'!$B:$B,"E2-F*") -> 4 | F6: =COUNTIF('Historias de Usuario'!$B:$B,"E2-B*") -> 4 | G6: =E6+F6 -> 8
B7: 3 | C7: Certificación y entregables | D7: Checklist de 10 entregables con trazabilidad (quién/cuándo), evidencias y generación del certificado de cierre. | E7: =COUNTIF('Historias de Usuario'!$B:$B,"E3-F*") -> 4 | F7: =COUNTIF('Historias de Usuario'!$B:$B,"E3-B*") -> 4 | G7: =E7+F7 -> 8
B8: 4 | C8: Impedimentos y riesgos | D8: Registro, seguimiento y resolución de impedimentos; clasificación del nivel de riesgo de cada HDU. | E8: =COUNTIF('Historias de Usuario'!$B:$B,"E4-F*") -> 4 | F8: =COUNTIF('Historias de Usuario'!$B:$B,"E4-B*") -> 4 | G8: =E8+F8 -> 8
B9: 5 | C9: Integración con Jira Cloud | D9: Sincronización de lectura de HDU desde Jira Cloud e importación alternativa por CSV/JSON. | E9: =COUNTIF('Historias de Usuario'!$B:$B,"E5-F*") -> 4 | F9: =COUNTIF('Historias de Usuario'!$B:$B,"E5-B*") -> 4 | G9: =E9+F9 -> 8
B10: 6 | C10: Indicadores y dashboards | D10: Dashboards de cumplimiento, avance, riesgos, impedimentos y carga de trabajo para la supervisión del QE. | E10: =COUNTIF('Historias de Usuario'!$B:$B,"E6-F*") -> 4 | F10: =COUNTIF('Historias de Usuario'!$B:$B,"E6-B*") -> 4 | G10: =E10+F10 -> 8
B11: Total | E11: =SUM(E5:E10) -> 33 | F11: =SUM(F5:F10) -> 33 | G11: =SUM(G5:G10) -> 66

Sheet Relación Front-Back
B1: Relación entre HDU de Frontend y Backend
B2: Cada funcionalidad visible por el usuario se sostiene en las reglas de backend que la hacen posible.
B4: Épica | C4: Funcionalidad | D4: HDU Frontend | E4: HDU Backend
B5: E1 | C5: Inicio de sesión | D5: E1-F01 | E5: E1-B01, E1-B02
C6: Portal e inicio del QE | D6: E1-F02, E1-F03 | E6: E1-B02, E1-B03
C7: Equipo supervisado | D7: E1-F04 | E7: E1-B04
C8: Portal e inicio del QA | D8: E1-F05, E1-F06 | E8: E1-B02, E1-B05
C9: Portal e inicio administrativo | D9: E1-F07, E1-F08 | E9: E1-B02, E1-B06
C10: Usuarios y roles | D10: E1-F09 | E10: E1-B07, E1-B08, E1-B12
C11: Supervisión | D11: E1-F10 | E11: E1-B09, E1-B12
C12: Perfil | D12: E1-F11 | E12: E1-B10
C13: Cierre de sesión | D13: E1-F12 | E13: E1-B11
B14: E1 | C14: Recuperación de contraseña | D14: E1-F13 | E14: E1-B13
B16: E2 | C16: Registro de HDU | D16: E2-F01 | E16: E2-B01
C17: Asignación de analista | D17: E2-F02 | E17: E2-B03, E2-B04
C18: Listado y filtros | D18: E2-F03 | E18: E2-B03
C19: Detalle y estados | D19: E2-F04 | E19: E2-B02, E2-B04
B21: E3 | C21: Checklist de entregables | D21: E3-F01, E3-F02 | E21: E3-B01, E3-B02
C22: Aprobación del QE | D22: E3-F03 | E22: E3-B02, E3-B04
C23: Certificado | D23: E3-F04 | E23: E3-B03, E3-B04
B25: E4 | C25: Registro de impedimentos | D25: E4-F01 | E25: E4-B01
C26: Gestión de impedimentos | D26: E4-F02, E4-F03 | E26: E4-B02, E4-B04
C27: Nivel de riesgo | D27: E4-F04 | E27: E4-B03, E4-B04
B29: E5 | C29: Configuración Jira | D29: E5-F01 | E29: E5-B01
C30: Sincronización Jira | D30: E5-F02 | E30: E5-B02, E5-B04
C31: Importación CSV/JSON | D31: E5-F03 | E31: E5-B03, E5-B04
C32: Historial de integración | D32: E5-F04 | E32: E5-B04
B34: E6 | C34: Dashboard de cumplimiento | D34: E6-F01 | E34: E6-B01
C35: Semáforo y carga | D35: E6-F02, E6-F03 | E35: E6-B02
C36: Tendencia y exportación | D36: E6-F04 | E36: E6-B03, E6-B04

Sheet Instructivo
B1: Historias de usuario y criterios de aceptación: Instructivo
B4: Columna | C4: Instrucciones
B5: Identificador (ID) de la historia | C5: Código que identifica unívocamente a la historia en el proyecto que se esté desarrollando. El formato debe ser elegido por el equipo.
B6: Rol | C6: Es el rol que está desempeñando el usuario cuando utiliza la funcionalidad que se está describiendo. Debe ser lo más especifico posible, describiendo el rol o actor que se está desempeñando. El enunciado puede escribirse como se sigue: Yo como un [Rol], desempeñando el rol de [Rol], como un [Rol], entre otros. Por ejemplo: Yo como cliente registrado. Desempeñando el rol de cliente registrado. Como un cliente registrado.
B7: Característica / Funcionalidad | C7: Representa la función que el rol quiere o necesita hacer en el sistema que se está desarrollando. Puede diferenciarse entre acciones obligatorias u opcionales, utilizando la palabra puede o necesita para describir la acción. Por ejemplo: Necesito realizar búsquedas de productos por categorías. Puedo seleccionar una categoría para ver el número de productos que tiene asociado.
B8: Razón / Resultado | C8: Lo que el rol necesita lograr al ejecutar la acción. Este es el resultado de ejecutar la acción desde el punto de vista del rol. Este punto puede ser opcional, pues la historia puede documentarse sólo con la definición del rol y la acción (sin definir la consecuencia).
B9: Número (#) de escenario | C9: Número (ejemplo 1, 2, 3 ó 4), que identifica al escenario asociado a la historia.
B10: Criterio de aceptación (título) | C10: Describe el contexto del escenario que define un comportamiento. Por ejemplo, si se toma el ejemplo de búsquedas de productos por categoría, un posible ejemplo pudiera ser: Categoría sin productos asociados.
B11: Contexto | C11: Proporciona mayor descripción sobre las condiciones que desencadenan el escenario.
B12: Evento | C12: Representa la acción que el usuario ejecuta, en el contexto definido para el escenario.
B13: Resultado / Comportamiento esperado | C13: Dado el contexto y la acción ejecutada por el usuario, la consecuencia es el comportamiento del sistema en esa situación.
B14: Epica | C14: Número de la épica a la que pertenece la historia. Ver hoja Épicas para nombre y descripción de cada una.

Sheet CDP-Sprint 1
B1: Casos de prueba · Sprint 1 · Épica 1: acceso, portales por rol y organización QA
B2: Un caso por escenario de aceptación. Las pruebas automatizadas indicadas se ejecutan sobre el stack real (Supabase, servicios y datos semilla). Resultado de la última regresión: 256 de 257 pruebas pasan (1 omitida: límite de intentos, inexistente en Supabase local).
B4: Caso de Prueba | C4: HDU | D4: Escenario (#) | E4: Análisis de Funcionalidades | F4: Descripción | G4: Precondiciones | H4: Pasos | I4: Resultados Esperados | J4: Tipo de prueba | K4: Prueba automatizada | L4: Resultado obtenido | M4: Fecha de ejecución | N4: Observaciones
B5: CP-S1-001: Formulario de ingreso | C5: E1-F01 | D5: 1 | E5: Formulario de ingreso | F5: Verificar que se muestran los campos de correo y contraseña, con opción de mostrar u ocultar la contraseña. | G5: El usuario accede a la pantalla de inicio de sesión. Stack local con Supabase, servicios y datos semilla. | H5: 1. Abrir el portal (http://localhost:5173). 2. Visualiza el formulario. 3. Verificar en pantalla el resultado esperado. | I5: Se muestran los campos de correo y contraseña, con opción de mostrar u ocultar la contraseña. | J5: Unitaria (Vitest) + E2E (Playwright) | K5: apps/web/src/test/login.test.tsx tests/e2e/e1-f01-login.spec.ts | L5: Aprobado | M5: 46281 | N5: Certificado el 16-09-2026; re-ejecutado sin regresión el 16-10-2026.
B6: CP-S1-002: Campos obligatorios | C6: E1-F01 | D6: 2 | E6: Campos obligatorios | F6: Verificar que el sistema valida los campos obligatorios y marca los que faltan sin enviar la solicitud. | G6: El usuario deja el correo o la contraseña en blanco. Stack local con Supabase, servicios y datos semilla. | H6: 1. Abrir el portal (http://localhost:5173). 2. Presiona Ingresar. 3. Verificar en pantalla el resultado esperado. | I6: El sistema valida los campos obligatorios y marca los que faltan sin enviar la solicitud. | J6: Unitaria (Vitest) + E2E (Playwright) | K6: apps/web/src/test/login.test.tsx tests/e2e/e1-f01-login.spec.ts | L6: Aprobado | M6: 46281 | N6: Certificado el 16-09-2026; re-ejecutado sin regresión el 16-10-2026.
B7: CP-S1-003: Credenciales incorrectas | C7: E1-F01 | D7: 3 | E7: Credenciales incorrectas | F7: Verificar que se indica que el ingreso está en proceso y luego se presenta un mensaje genérico de credenciales incorrectas, sin revelar si el correo existe. | G7: El usuario ingresa credenciales válidas en formato pero incorrectas. Stack local con Supabase, servicios y datos semilla. | H7: 1. Abrir el portal (http://localhost:5173). 2. Presiona Ingresar. 3. Verificar en pantalla el resultado esperado. | I7: Se indica que el ingreso está en proceso y luego se presenta un mensaje genérico de credenciales incorrectas, sin revelar si el correo existe. | J7: Unitaria (Vitest) + E2E (Playwright) | K7: apps/web/src/test/login.test.tsx tests/e2e/e1-f01-login.spec.ts | L7: Aprobado | M7: 46281 | N7: Certificado el 16-09-2026; re-ejecutado sin regresión el 16-10-2026.
B8: CP-S1-004: Redirección al portal QE | C8: E1-F02 | D8: 1 | E8: Redirección al portal QE | F8: Verificar que es dirigido a su portal, que muestra su identidad y la navegación de supervisión. | G8: El usuario tiene rol QE y credenciales válidas. Sesión de Quality Engineer (QE) (carla.fuentes@quality360.local). Stack local con Supabase, servicios y datos semilla. | H8: 1. Abrir el portal (http://localhost:5173) e iniciar sesión como Quality Engineer (QE). 2. Inicia sesión. 3. Verificar en pantalla el resultado esperado. | I8: Es dirigido a su portal, que muestra su identidad y la navegación de supervisión. | J8: E2E (Playwright) | K8: tests/e2e/e1-f02-portal-qe.spec.ts tests/e2e/login-redireccion-rol.spec.ts | L8: Aprobado | M8: 46281 | N8: Certificado el 16-09-2026; re-ejecutado sin regresión el 16-10-2026.
B9: CP-S1-005: Acceso a ruta de otro rol | C9: E1-F02 | D9: 2 | E9: Acceso a ruta de otro rol | F9: Verificar que se presenta acceso denegado o se redirige al portal autorizado. | G9: El QE está autenticado. Sesión de Quality Engineer (QE) (carla.fuentes@quality360.local). Stack local con Supabase, servicios y datos semilla. | H9: 1. Abrir el portal (http://localhost:5173) e iniciar sesión como Quality Engineer (QE). 2. Intenta abrir una ruta administrativa o de analista. 3. Verificar en pantalla el resultado esperado. | I9: Se presenta acceso denegado o se redirige al portal autorizado. | J9: E2E (Playwright) | K9: tests/e2e/e1-f02-portal-qe.spec.ts | L9: Aprobado | M9: 46281 | N9: Certificado el 16-09-2026; re-ejecutado sin regresión el 16-10-2026.
B10: CP-S1-006: Navegación disponible | C10: E1-F02 | D10: 3 | E10: Navegación disponible | F10: Verificar que solo aparecen opciones de supervisión (equipo, historias supervisadas, perfil, cerrar sesión). | G10: El QE está en su portal. Sesión de Quality Engineer (QE) (carla.fuentes@quality360.local). Stack local con Supabase, servicios y datos semilla. | H10: 1. Abrir el portal (http://localhost:5173) e iniciar sesión como Quality Engineer (QE). 2. Revisa el menú. 3. Verificar en pantalla el resultado esperado. | I10: Solo aparecen opciones de supervisión (equipo, historias supervisadas, perfil, cerrar sesión). | J10: E2E (Playwright) | K10: tests/e2e/e1-f02-portal-qe.spec.ts | L10: Aprobado | M10: 46281 | N10: Certificado el 16-09-2026; re-ejecutado sin regresión el 16-10-2026.
B11: CP-S1-007: Resumen con datos | C11: E1-F03 | D11: 1 | E11: Resumen con datos | F11: Verificar que se muestra la cantidad de analistas supervisados y de HDU bajo supervisión, con acceso a ambos listados. | G11: El QE tiene analistas e historias asignadas. Sesión de Quality Engineer (QE) (carla.fuentes@quality360.local). Stack local con Supabase, servicios y datos semilla. | H11: 1. Abrir el portal (http://localhost:5173) e iniciar sesión como Quality Engineer (QE). 2. Ingresa al panel de inicio. 3. Verificar en pantalla el resultado esperado. | I11: Se muestra la cantidad de analistas supervisados y de HDU bajo supervisión, con acceso a ambos listados. | J11: E2E (Playwright) | K11: tests/e2e/e1-f03-qe-inicio.spec.ts | L11: Aprobado | M11: 46281 | N11: Certificado el 16-09-2026; re-ejecutado sin regresión el 16-10-2026.
B12: CP-S1-008: Sin datos | C12: E1-F03 | D12: 2 | E12: Sin datos | F12: Verificar que se informa explícitamente la ausencia de datos, sin mostrar cifras ficticias. | G12: El QE no tiene analistas ni historias asignadas. Sesión de Quality Engineer (QE) (carla.fuentes@quality360.local). Stack local con Supabase, servicios y datos semilla. | H12: 1. Abrir el portal (http://localhost:5173) e iniciar sesión como Quality Engineer (QE). 2. Ingresa al panel de inicio. 3. Verificar en pantalla el resultado esperado. | I12: Se informa explícitamente la ausencia de datos, sin mostrar cifras ficticias. | J12: E2E (Playwright) | K12: tests/e2e/e1-f03-qe-inicio.spec.ts | L12: Aprobado | M12: 46281 | N12: Certificado el 16-09-2026; re-ejecutado sin regresión el 16-10-2026.
B13: CP-S1-009: Error de consulta | C13: E1-F03 | D13: 3 | E13: Error de consulta | F13: Verificar que se diferencia el estado de error del estado de carga y de la ausencia de datos, con opción de reintentar. | G13: El servicio de resumen no responde. Sesión de Quality Engineer (QE) (carla.fuentes@quality360.local). Stack local con Supabase, servicios y datos semilla. | H13: 1. Abrir el portal (http://localhost:5173) e iniciar sesión como Quality Engineer (QE). 2. Ingresa al panel de inicio. 3. Verificar en pantalla el resultado esperado. | I13: Se diferencia el estado de error del estado de carga y de la ausencia de datos, con opción de reintentar. | J13: E2E (Playwright) | K13: tests/e2e/fuente-caida-inicio.spec.ts | L13: Aprobado | M13: 46281 | N13: Certificado el 16-09-2026; re-ejecutado sin regresión el 16-10-2026.
B14: CP-S1-010: Listado vigente | C14: E1-F04 | D14: 1 | E14: Listado vigente | F14: Verificar que se muestran únicamente los analistas con supervisión vigente, identificados por nombre y correo. | G14: El QE tiene relaciones de supervisión vigentes. Sesión de Quality Engineer (QE) (carla.fuentes@quality360.local). Stack local con Supabase, servicios y datos semilla. | H14: 1. Abrir el portal (http://localhost:5173) e iniciar sesión como Quality Engineer (QE). 2. Abre la sección de analistas. 3. Verificar en pantalla el resultado esperado. | I14: Se muestran únicamente los analistas con supervisión vigente, identificados por nombre y correo. | J14: E2E (Playwright) | K14: tests/e2e/e1-f04-qe-equipo.spec.ts | L14: Aprobado | M14: 46281 | N14: Certificado el 16-09-2026; re-ejecutado sin regresión el 16-10-2026.
B15: CP-S1-011: Relaciones finalizadas | C15: E1-F04 | D15: 2 | E15: Relaciones finalizadas | F15: Verificar que el analista reasignado no aparece en el listado. | G15: Un analista fue reasignado a otro QE. Sesión de Quality Engineer (QE) (carla.fuentes@quality360.local). Stack local con Supabase, servicios y datos semilla. | H15: 1. Abrir el portal (http://localhost:5173) e iniciar sesión como Quality Engineer (QE). 2. Abre la sección de analistas. 3. Verificar en pantalla el resultado esperado. | I15: El analista reasignado no aparece en el listado. | J15: E2E (Playwright) | K15: tests/e2e/e1-f04-qe-equipo.spec.ts | L15: Aprobado | M15: 46281 | N15: Certificado el 16-09-2026; re-ejecutado sin regresión el 16-10-2026.
B16: CP-S1-012: Sin analistas | C16: E1-F04 | D16: 3 | E16: Sin analistas | F16: Verificar que se informa que no hay analistas asignados. | G16: El QE no tiene analistas asignados. Sesión de Quality Engineer (QE) (carla.fuentes@quality360.local). Stack local con Supabase, servicios y datos semilla. | H16: 1. Abrir el portal (http://localhost:5173) e iniciar sesión como Quality Engineer (QE). 2. Abre la sección de analistas. 3. Verificar en pantalla el resultado esperado. | I16: Se informa que no hay analistas asignados. | J16: E2E (Playwright) | K16: tests/e2e/e1-f04-qe-equipo.spec.ts | L16: Aprobado | M16: 46281 | N16: Certificado el 16-09-2026; re-ejecutado sin regresión el 16-10-2026.
... B76: CP-S1-072: Datos sensibles | C76: E1-B12 | D76: 3 | E76: Datos sensibles | F76: Verificar que se excluyen contraseñas y tokens de los registros. | G76: Se registra un cambio de credenciales. Sesión de Administrador (patricia.rojas@quality360.local). Stack local con Supabase, servicios y datos semilla. | H76: 1. Preparar el contexto: se registra un cambio de credenciales. 2. Se genera el registro a través del gateway o del proveedor de autenticación. 3. Verificar la respuesta (código HTTP y cuerpo) y los datos persistidos. | I76: Se excluyen contraseñas y tokens de los registros. | J76: API (Playwright) | K76: tests/api/e1-b12-auditoria.spec.ts | L76: Aprobado | M76: 46281 | N76: Certificado el 16-09-2026; re-ejecutado sin regresión el 16-10-2026.

Sheet CDP-Sprint 2
B1: Casos de prueba · Sprint 2 · Épica 2: gestión de historias de usuario (HDU)
B2: Un caso por escenario de aceptación. Las pruebas automatizadas indicadas se ejecutan sobre el stack real (Supabase, servicios y datos semilla). Resultado de la última regresión: 256 de 257 pruebas pasan (1 omitida: límite de intentos, inexistente en Supabase local).
B4: Caso de Prueba | C4: HDU | D4: Escenario (#) | E4: Análisis de Funcionalidades | F4: Descripción | G4: Precondiciones | H4: Pasos | I4: Resultados Esperados | J4: Tipo de prueba | K4: Prueba automatizada | L4: Resultado obtenido | M4: Fecha de ejecución | N4: Observaciones
B5: CP-S2-001: Registro exitoso | C5: E2-F01 | D5: 1 | E5: Registro exitoso | F5: Verificar que la HDU se crea en estado Pendiente y aparece en el listado. | G5: El QE completa el formulario con datos válidos. Sesión de Quality Engineer (QE) (carla.fuentes@quality360.local). Stack local con Supabase, servicios y datos semilla. | H5: 1. Abrir el portal (http://localhost:5173) e iniciar sesión como Quality Engineer (QE). 2. Presiona Guardar. 3. Verificar en pantalla el resultado esperado. | I5: La HDU se crea en estado Pendiente y aparece en el listado. | J5: E2E (Playwright) | K5: tests/e2e/e2-f01-crear-hdu.spec.ts | L5: Aprobado | M5: 46281 | N5: Certificado el 16-09-2026; re-ejecutado sin regresión el 16-10-2026.
B6: CP-S2-002: Datos obligatorios | C6: E2-F01 | D6: 2 | E6: Datos obligatorios | F6: Verificar que se indican los campos faltantes y no se crea la HDU. | G6: Faltan el identificador o el título. Sesión de Quality Engineer (QE) (carla.fuentes@quality360.local). Stack local con Supabase, servicios y datos semilla. | H6: 1. Abrir el portal (http://localhost:5173) e iniciar sesión como Quality Engineer (QE). 2. Presiona Guardar. 3. Verificar en pantalla el resultado esperado. | I6: Se indican los campos faltantes y no se crea la HDU. | J6: E2E (Playwright) | K6: tests/e2e/e2-f01-crear-hdu.spec.ts | L6: Aprobado | M6: 46281 | N6: Certificado el 16-09-2026; re-ejecutado sin regresión el 16-10-2026.
B7: CP-S2-003: Identificador duplicado | C7: E2-F01 | D7: 3 | E7: Identificador duplicado | F7: Verificar que se informa el duplicado y se solicita corregirlo. | G7: Ya existe una HDU con el mismo identificador. Sesión de Quality Engineer (QE) (carla.fuentes@quality360.local). Stack local con Supabase, servicios y datos semilla. | H7: 1. Abrir el portal (http://localhost:5173) e iniciar sesión como Quality Engineer (QE). 2. Presiona Guardar. 3. Verificar en pantalla el resultado esperado. | I7: Se informa el duplicado y se solicita corregirlo. | J7: E2E (Playwright) | K7: tests/e2e/e2-f01-crear-hdu.spec.ts | L7: Aprobado | M7: 46281 | N7: Certificado el 16-09-2026; re-ejecutado sin regresión el 16-10-2026.
B8: CP-S2-004: Asignación desde mi equipo | C8: E2-F02 | D8: 1 | E8: Asignación desde mi equipo | F8: Verificar que la HDU queda asignada y visible para ese analista. | G8: El QE abre una HDU sin analista. Sesión de Quality Engineer (QE) (carla.fuentes@quality360.local). Stack local con Supabase, servicios y datos semilla. | H8: 1. Abrir el portal (http://localhost:5173) e iniciar sesión como Quality Engineer (QE). 2. Selecciona un analista supervisado. 3. Verificar en pantalla el resultado esperado. | I8: La HDU queda asignada y visible para ese analista. | J8: E2E (Playwright) | K8: tests/e2e/e2-f02-asignar-analista.spec.ts | L8: Aprobado | M8: 46281 | N8: Certificado el 16-09-2026; re-ejecutado sin regresión el 16-10-2026.
B9: CP-S2-005: Analista fuera del equipo | C9: E2-F02 | D9: 2 | E9: Analista fuera del equipo | F9: Verificar que solo se listan analistas de su equipo. | G9: El QE busca un analista que no supervisa. Sesión de Quality Engineer (QE) (carla.fuentes@quality360.local). Stack local con Supabase, servicios y datos semilla. | H9: 1. Abrir el portal (http://localhost:5173) e iniciar sesión como Quality Engineer (QE). 2. Despliega el selector. 3. Verificar en pantalla el resultado esperado. | I9: Solo se listan analistas de su equipo. | J9: E2E (Playwright) | K9: tests/e2e/e2-f02-asignar-analista.spec.ts | L9: Aprobado | M9: 46281 | N9: Certificado el 16-09-2026; re-ejecutado sin regresión el 16-10-2026.
B10: CP-S2-006: Reasignación | C10: E2-F02 | D10: 3 | E10: Reasignación | F10: Verificar que se solicita confirmación y se registra el cambio. | G10: La HDU ya tiene analista. Sesión de Quality Engineer (QE) (carla.fuentes@quality360.local). Stack local con Supabase, servicios y datos semilla. | H10: 1. Abrir el portal (http://localhost:5173) e iniciar sesión como Quality Engineer (QE). 2. Selecciona otro analista y confirma. 3. Verificar en pantalla el resultado esperado. | I10: Se solicita confirmación y se registra el cambio. | J10: E2E (Playwright) | K10: tests/e2e/e2-f02-asignar-analista.spec.ts | L10: Aprobado | M10: 46281 | N10: Certificado el 16-09-2026; re-ejecutado sin regresión el 16-10-2026.
B11: CP-S2-007: Listado filtrado | C11: E2-F03 | D11: 1 | E11: Listado filtrado | F11: Verificar que se muestran solo las HDU del sprint elegido. | G11: El analista tiene HDU en varios sprints. Sesión de Analista QA (ana.torres@quality360.local). Stack local con Supabase, servicios y datos semilla. | H11: 1. Abrir el portal (http://localhost:5173) e iniciar sesión como Analista QA. 2. Aplica el filtro por sprint. 3. Verificar en pantalla el resultado esperado. | I11: Se muestran solo las HDU del sprint elegido. | J11: E2E (Playwright) | K11: tests/e2e/e2-f03-listado-hdu.spec.ts | L11: Aprobado | M11: 46281 | N11: Certificado el 16-09-2026; re-ejecutado sin regresión el 16-10-2026.
B12: CP-S2-008: Sin resultados | C12: E2-F03 | D12: 2 | E12: Sin resultados | F12: Verificar que se informa que no hay HDU con esos criterios. | G12: Ningún registro cumple los filtros. Sesión de Analista QA (ana.torres@quality360.local). Stack local con Supabase, servicios y datos semilla. | H12: 1. Abrir el portal (http://localhost:5173) e iniciar sesión como Analista QA. 2. Aplica los filtros. 3. Verificar en pantalla el resultado esperado. | I12: Se informa que no hay HDU con esos criterios. | J12: E2E (Playwright) | K12: tests/e2e/e2-f03-listado-hdu.spec.ts | L12: Aprobado | M12: 46281 | N12: Certificado el 16-09-2026; re-ejecutado sin regresión el 16-10-2026.
B13: CP-S2-009: Solo mis historias | C13: E2-F03 | D13: 3 | E13: Solo mis historias | F13: Verificar que solo aparecen HDU asignadas a él. | G13: El analista consulta el listado. Sesión de Analista QA (ana.torres@quality360.local). Stack local con Supabase, servicios y datos semilla. | H13: 1. Abrir el portal (http://localhost:5173) e iniciar sesión como Analista QA. 2. Visualiza los resultados. 3. Verificar en pantalla el resultado esperado. | I13: Solo aparecen HDU asignadas a él. | J13: E2E (Playwright) | K13: tests/e2e/e2-f03-listado-hdu.spec.ts | L13: Aprobado | M13: 46281 | N13: Certificado el 16-09-2026; re-ejecutado sin regresión el 16-10-2026.
B14: CP-S2-010: Detalle completo | C14: E2-F04 | D14: 1 | E14: Detalle completo | F14: Verificar que se muestran datos, QE, analista, estado, célula, sprint y avance del checklist. | G14: El usuario tiene acceso a la HDU. Stack local con Supabase, servicios y datos semilla. | H14: 1. Abrir el portal (http://localhost:5173). 2. Abre el detalle. 3. Verificar en pantalla el resultado esperado. | I14: Se muestran datos, QE, analista, estado, célula, sprint y avance del checklist. | J14: E2E (Playwright) | K14: tests/e2e/e2-f04-detalle-hdu.spec.ts | L14: Aprobado | M14: 46281 | N14: Certificado el 16-09-2026; re-ejecutado sin regresión el 16-10-2026.
B15: CP-S2-011: HDU sin acceso | C15: E2-F04 | D15: 2 | E15: HDU sin acceso | F15: Verificar que se presenta acceso denegado. | G15: El usuario no está relacionado con la HDU. Stack local con Supabase, servicios y datos semilla. | H15: 1. Abrir el portal (http://localhost:5173). 2. Intenta abrir el detalle. 3. Verificar en pantalla el resultado esperado. | I15: Se presenta acceso denegado. | J15: E2E (Playwright) | K15: tests/e2e/e2-f04-detalle-hdu.spec.ts | L15: Aprobado | M15: 46281 | N15: Certificado el 16-09-2026; re-ejecutado sin regresión el 16-10-2026.
B16: CP-S2-012: Cambio de estado | C16: E2-F04 | D16: 3 | E16: Cambio de estado | F16: Verificar que se actualiza el estado y se muestra la fecha del cambio. | G16: El usuario autorizado está en el detalle. Stack local con Supabase, servicios y datos semilla. | H16: 1. Abrir el portal (http://localhost:5173). 2. Cambia el estado a uno válido. 3. Verificar en pantalla el resultado esperado. | I16: Se actualiza el estado y se muestra la fecha del cambio. | J16: E2E (Playwright) | K16: tests/e2e/e2-f04-detalle-hdu.spec.ts | L16: Aprobado | M16: 46281 | N16: Certificado el 16-09-2026; re-ejecutado sin regresión el 16-10-2026.
... B28: CP-S2-024: Consulta del historial | C28: E2-B04 | D28: 3 | E28: Consulta del historial | F28: Verificar que se devuelve en orden cronológico. | G28: Un usuario autorizado solicita el historial. Sesión de Administrador (patricia.rojas@quality360.local). Stack local con Supabase, servicios y datos semilla. | H28: 1. Preparar el contexto: un usuario autorizado solicita el historial. 2. Se procesa la consulta a través del gateway o del proveedor de autenticación. 3. Verificar la respuesta (código HTTP y cuerpo) y los datos persistidos. | I28: Se devuelve en orden cronológico. | J28: API (Playwright) | K28: tests/api/e2-b04-historial-hdu.spec.ts | L28: Aprobado | M28: 46281 | N28: Certificado el 16-09-2026; re-ejecutado sin regresión el 16-10-2026.

Sheet CDP-Sprint 3
B1: Casos de prueba · Sprint 3 (actual) · Épica 3: certificación y entregables, más el rediseño del inicio de sesión y la recuperación de contraseña (E1-F13, E1-B13)
B2: Un caso por escenario de aceptación. Las pruebas automatizadas indicadas se ejecutan sobre el stack real (Supabase, servicios y datos semilla). Resultado de la última regresión: 256 de 257 pruebas pasan (1 omitida: límite de intentos, inexistente en Supabase local).
B4: Caso de Prueba | C4: HDU | D4: Escenario (#) | E4: Análisis de Funcionalidades | F4: Descripción | G4: Precondiciones | H4: Pasos | I4: Resultados Esperados | J4: Tipo de prueba | K4: Prueba automatizada | L4: Resultado obtenido | M4: Fecha de ejecución | N4: Observaciones
B5: CP-S3-001: Solicitud del enlace | C5: E1-F13 | D5: 1 | E5: Solicitud del enlace | F5: Verificar que se valida que el correo sea obligatorio y tenga formato válido, y se muestra siempre la misma confirmación, sin revelar si el correo está registrado. | G5: El usuario está en la pantalla de inicio de sesión. Stack local con Supabase, servicios y datos semilla. | H5: 1. Abrir el portal (http://localhost:5173). 2. Selecciona «¿Olvidaste tu contraseña?», ingresa su correo y presiona Enviar enlace. 3. Verificar en pantalla el resultado esperado. | I5: Se valida que el correo sea obligatorio y tenga formato válido, y se muestra siempre la misma confirmación, sin revelar si el correo está registrado. | J5: Unitaria (Vitest) + E2E (Playwright) | K5: apps/web/src/test/login.test.tsx apps/web/src/test/recuperacion.test.tsx tests/e2e/recuperacion-contrasena-ui.spec.ts | L5: Aprobado | M5: 46311 | N5: Certificado el 16-10-2026 (docs/validacion/certificacion-login.md).
B6: CP-S3-002: Nueva contraseña | C6: E1-F13 | D6: 2 | E6: Nueva contraseña | F6: Verificar que se exige un mínimo de 8 caracteres y que ambas coincidan. Al guardar, se cierra la sesión de recuperación y el usuario vuelve al inicio de sesión con un aviso de contraseña actualizada. | G6: El usuario abre el enlace recibido por correo. Stack local con Supabase, servicios y datos semilla. | H6: 1. Abrir el portal (http://localhost:5173). 2. Ingresa y repite la nueva contraseña y presiona Guardar. 3. Verificar en pantalla el resultado esperado. | I6: Se exige un mínimo de 8 caracteres y que ambas coincidan. Al guardar, se cierra la sesión de recuperación y el usuario vuelve al inicio de sesión con un aviso de contraseña actualizada. | J6: Unitaria (Vitest) + E2E (Playwright) | K6: apps/web/src/test/errorAcceso.test.ts apps/web/src/test/recuperacion.test.tsx tests/e2e/recuperacion-contrasena-ui.spec.ts | L6: Aprobado | M6: 46311 | N6: Certificado el 16-10-2026 (docs/validacion/certificacion-login.md).
B7: CP-S3-003: Enlace inválido o ya usado | C7: E1-F13 | D7: 3 | E7: Enlace inválido o ya usado | F7: Verificar que se informa que el enlace no es válido y se ofrece solicitar uno nuevo, sin dar acceso al portal. | G7: El enlace expiró o ya fue utilizado. Stack local con Supabase, servicios y datos semilla. | H7: 1. Abrir el portal (http://localhost:5173). 2. El usuario lo abre. 3. Verificar en pantalla el resultado esperado. | I7: Se informa que el enlace no es válido y se ofrece solicitar uno nuevo, sin dar acceso al portal. | J7: Unitaria (Vitest) + E2E (Playwright) | K7: apps/web/src/test/errorAcceso.test.ts apps/web/src/test/recuperacion.test.tsx tests/e2e/recuperacion-contrasena-ui.spec.ts | L7: Aprobado | M7: 46311 | N7: Certificado el 16-10-2026 (docs/validacion/certificacion-login.md).
B8: CP-S3-004: Envío del enlace | C8: E1-B13 | D8: 1 | E8: Envío del enlace | F8: Verificar que solo si el correo está registrado se envía un enlace de un solo uso, válido por un tiempo limitado. La respuesta es idéntica para correos registrados e inexistentes. | G8: Se solicita la recuperación para un correo. Stack local con Supabase, servicios y datos semilla. | H8: 1. Preparar el contexto: se solicita la recuperación para un correo. 2. El proveedor de autenticación procesa la solicitud a través del gateway o del proveedor de autenticación. 3. Verificar la respuesta (código HTTP y cuerpo) y los datos persistidos. | I8: Solo si el correo está registrado se envía un enlace de un solo uso, válido por un tiempo limitado. La respuesta es idéntica para correos registrados e inexistentes. | J8: Unitaria (Vitest) + API (Playwright) + E2E (Playwright) | K8: apps/web/src/test/recuperacionSupabase.test.ts tests/api/recuperacion-contrasena.spec.ts tests/e2e/recuperacion-contrasena-ui.spec.ts | L8: Aprobado | M8: 46311 | N8: Certificado el 16-10-2026 (docs/validacion/certificacion-login.md).
B9: CP-S3-005: Cambio de contraseña | C9: E1-B13 | D9: 2 | E9: Cambio de contraseña | F9: Verificar que la contraseña anterior deja de ser válida, las sesiones previas no pueden renovarse y la sesión de recuperación no habilita el acceso al portal. | G9: Se usa un enlace válido. Stack local con Supabase, servicios y datos semilla. | H9: 1. Preparar el contexto: se usa un enlace válido. 2. Se fija la nueva contraseña a través del gateway o del proveedor de autenticación. 3. Verificar la respuesta (código HTTP y cuerpo) y los datos persistidos. | I9: La contraseña anterior deja de ser válida, las sesiones previas no pueden renovarse y la sesión de recuperación no habilita el acceso al portal. | J9: API (Playwright) + E2E (Playwright) | K9: tests/api/recuperacion-contrasena.spec.ts tests/e2e/recuperacion-contrasena-ui.spec.ts | L9: Aprobado | M9: 46311 | N9: Certificado el 16-10-2026 (docs/validacion/certificacion-login.md).
B10: CP-S3-006: Redirección y abuso | C10: E1-B13 | D10: 3 | E10: Redirección y abuso | F10: Verificar que solo se redirige a direcciones autorizadas y se limita la frecuencia de envíos, sin revelar si el correo existe. | G10: Se solicita con una dirección de retorno no autorizada o se repiten las solicitudes. Stack local con Supabase, servicios y datos semilla. | H10: 1. Preparar el contexto: se solicita con una dirección de retorno no autorizada o se repiten las solicitudes. 2. El proveedor procesa la solicitud a través del gateway o del proveedor de autenticación. 3. Verificar la respuesta (código HTTP y cuerpo) y los datos persistidos. | I10: Solo se redirige a direcciones autorizadas y se limita la frecuencia de envíos, sin revelar si el correo existe. | J10: API (Playwright) + E2E (Playwright) | K10: tests/api/recuperacion-contrasena.spec.ts tests/e2e/recuperacion-contrasena-ui.spec.ts | L10: Aprobado con observación | M10: 46311 | N10: Certificado el 16-10-2026 (docs/validacion/certificacion-login.md). Redirección verificada; el límite de envíos de la nube queda pendiente.
B11: CP-S3-007: Checklist completo | C11: E3-F01 | D11: 1 | E11: Checklist completo | F11: Verificar que se muestran los 10 entregables en orden, con estado, responsable y fecha de cada uno. | G11: El analista abre una HDU. Sesión de Analista QA (ana.torres@quality360.local). Stack local con Supabase, servicios y datos semilla. | H11: 1. Abrir el portal (http://localhost:5173) e iniciar sesión como Analista QA. 2. Visualiza el checklist. 3. Verificar en pantalla el resultado esperado. | I11: Se muestran los 10 entregables en orden, con estado, responsable y fecha de cada uno. | J11: E2E (Playwright) | K11: tests/e2e/e3-f01-checklist.spec.ts | L11: Aprobado | M11: 46311 | N11: Certificado el 17-09-2026; re-ejecutado sin regresión tras el modelo de datos (12-10-2026) y el 16-10-2026.
B12: CP-S3-008: Porcentaje de cumplimiento | C12: E3-F01 | D12: 2 | E12: Porcentaje de cumplimiento | F12: Verificar que se muestra el porcentaje de avance calculado. | G12: Hay entregables completados. Sesión de Analista QA (ana.torres@quality360.local). Stack local con Supabase, servicios y datos semilla. | H12: 1. Abrir el portal (http://localhost:5173) e iniciar sesión como Analista QA. 2. Visualiza el checklist. 3. Verificar en pantalla el resultado esperado. | I12: Se muestra el porcentaje de avance calculado. | J12: E2E (Playwright) | K12: tests/e2e/e3-f01-checklist.spec.ts | L12: Aprobado | M12: 46311 | N12: Certificado el 17-09-2026; re-ejecutado sin regresión tras el modelo de datos (12-10-2026) y el 16-10-2026.
B13: CP-S3-009: Solo lectura | C13: E3-F01 | D13: 3 | E13: Solo lectura | F13: Verificar que no puede marcar entregables. | G13: Un usuario sin permiso abre la HDU. Sesión de Analista QA (ana.torres@quality360.local). Stack local con Supabase, servicios y datos semilla. | H13: 1. Abrir el portal (http://localhost:5173) e iniciar sesión como Analista QA. 2. Visualiza el checklist. 3. Verificar en pantalla el resultado esperado. | I13: No puede marcar entregables. | J13: E2E (Playwright) | K13: tests/e2e/e3-f01-checklist.spec.ts | L13: Aprobado | M13: 46311 | N13: Certificado el 17-09-2026; re-ejecutado sin regresión tras el modelo de datos (12-10-2026) y el 16-10-2026.
B14: CP-S3-010: Marcar con evidencia | C14: E3-F02 | D14: 1 | E14: Marcar con evidencia | F14: Verificar que queda completado con mi nombre y fecha. | G14: El entregable está pendiente. Sesión de Analista QA (ana.torres@quality360.local). Stack local con Supabase, servicios y datos semilla. | H14: 1. Abrir el portal (http://localhost:5173) e iniciar sesión como Analista QA. 2. Lo marca y adjunta un enlace o archivo. 3. Verificar en pantalla el resultado esperado. | I14: Queda completado con mi nombre y fecha. | J14: E2E (Playwright) | K14: tests/e2e/e3-f02-marcar-entregable.spec.ts | L14: Aprobado | M14: 46311 | N14: Certificado el 17-09-2026; re-ejecutado sin regresión tras el modelo de datos (12-10-2026) y el 16-10-2026.
B15: CP-S3-011: Orden del proceso | C15: E3-F02 | D15: 2 | E15: Orden del proceso | F15: Verificar que se informa que debe completar el anterior. | G15: El entregable anterior obligatorio está pendiente. Sesión de Analista QA (ana.torres@quality360.local). Stack local con Supabase, servicios y datos semilla. | H15: 1. Abrir el portal (http://localhost:5173) e iniciar sesión como Analista QA. 2. Intenta marcar el siguiente. 3. Verificar en pantalla el resultado esperado. | I15: Se informa que debe completar el anterior. | J15: E2E (Playwright) | K15: tests/e2e/e3-f02-marcar-entregable.spec.ts | L15: Aprobado | M15: 46311 | N15: Certificado el 17-09-2026; re-ejecutado sin regresión tras el modelo de datos (12-10-2026) y el 16-10-2026.
B16: CP-S3-012: Desmarcar | C16: E3-F02 | D16: 3 | E16: Desmarcar | F16: Verificar que se registra el retroceso y su motivo. | G16: El entregable está completado. Sesión de Analista QA (ana.torres@quality360.local). Stack local con Supabase, servicios y datos semilla. | H16: 1. Abrir el portal (http://localhost:5173) e iniciar sesión como Analista QA. 2. Lo desmarca indicando motivo. 3. Verificar en pantalla el resultado esperado. | I16: Se registra el retroceso y su motivo. | J16: E2E (Playwright) | K16: tests/e2e/e3-f02-marcar-entregable.spec.ts | L16: Aprobado | M16: 46311 | N16: Certificado el 17-09-2026; re-ejecutado sin regresión tras el modelo de datos (12-10-2026) y el 16-10-2026.
... B34: CP-S3-030: Consulta | C34: E3-B04 | D34: 3 | E34: Consulta | F34: Verificar que se devuelve el historial completo. | G34: Un usuario autorizado pide la bitácora de una HDU. Sesión de Administrador (patricia.rojas@quality360.local). Stack local con Supabase, servicios y datos semilla. | H34: 1. Preparar el contexto: un usuario autorizado pide la bitácora de una HDU. 2. Se procesa a través del gateway o del proveedor de autenticación. 3. Verificar la respuesta (código HTTP y cuerpo) y los datos persistidos. | I34: Se devuelve el historial completo. | J34: API (Playwright) | K34: tests/api/e3-b04-bitacora.spec.ts | L34: Aprobado | M34: 46311 | N34: Certificado el 17-09-2026; re-ejecutado sin regresión tras el modelo de datos (12-10-2026) y el 16-10-2026.
B35: CP-S3-031: Diseño responsivo del inicio de sesión | C35: E1-F01 (rediseño) | D35: — | E35: Diseño responsivo del inicio de sesión | F35: Verificar que la pantalla de acceso se adapta a 1280, 1024, 768, 390 y 320 px sin scroll horizontal, con logo visible y zonas táctiles de 44 px o más. | G35: Portal publicado con el rediseño «Acceso A». | H35: 1. Abrir /login en cada ancho de pantalla. 2. Medir el ancho del contenido y el tamaño de los controles. 3. Verificar la franja compacta bajo 1024 px. | I35: Sin scroll horizontal; panel de marca compacto bajo 1024 px; campos de 16 px en móvil; controles de 44 px o más. | J35: E2E (Playwright) | K35: tests/e2e/login-responsivo-a11y.spec.ts | L35: Aprobado | M35: 46311 | N35: Regresión del rediseño del inicio de sesión (Sprint 3).
B36: CP-S3-032: Accesibilidad del inicio de sesión | C36: E1-F01 (rediseño) | D36: — | E36: Accesibilidad del inicio de sesión | F36: Verificar etiquetas reales, foco visible, un único h1 y contraste suficiente en /login, /recuperar-contrasena y /restablecer-contrasena. | G36: Portal con el rediseño de acceso. | H36: 1. Recorrer las pantallas con teclado. 2. Revisar encabezados, etiquetas y contraste. 3. Verificar los nombres accesibles del botón de mostrar contraseña. | I36: Un único h1 por pantalla, etiquetas asociadas, foco visible y contraste de 4,5:1 en textos y 3:1 en bordes. | J36: E2E (Playwright) | K36: tests/e2e/login-responsivo-a11y.spec.ts | L36: Aprobado | M36: 46311 | N36: Regresión del rediseño del inicio de sesión (Sprint 3).
B37: CP-S3-033: Alertas de demasiados intentos y servicio no disponible | C37: E1-F01 (rediseño) | D37: — | E37: Alertas de demasiados intentos y servicio no disponible | F37: Verificar que el login distingue el error 429 y las fallas de red o 5xx del mensaje genérico de credenciales. | G37: Respuestas del proveedor simuladas: 429 over_request_rate_limit, corte de red y 503. | H37: 1. Ingresar correo y contraseña. 2. Presionar Ingresar con cada respuesta simulada. 3. Verificar el texto y el tipo de la alerta. | I37: 429: «Demasiados intentos de ingreso…». Red o 5xx: «No pudimos conectar con el servicio de autenticación…». | J37: E2E (Playwright) | K37: tests/e2e/login-redireccion-rol.spec.ts | L37: Aprobado | M37: 46311 | N37: Regresión del rediseño del inicio de sesión (Sprint 3).
B38: CP-S3-034: Navegación segura tras el ingreso | C38: E1-B01 (rediseño) | D38: — | E38: Navegación segura tras el ingreso | F38: Verificar que ningún parámetro de la URL redirige a otro origen después de iniciar sesión. | G38: Usuario de la semilla con credenciales válidas. | H38: 1. Abrir /login con parámetros de retorno hacia otro dominio. 2. Iniciar sesión. 3. Verificar el destino. | I38: El usuario siempre queda dentro del portal de su rol. | J38: E2E (Playwright) | K38: tests/e2e/recuperacion-contrasena-ui.spec.ts | L38: Aprobado | M38: 46311 | N38: Regresión del rediseño del inicio de sesión (Sprint 3).

Sheet Resumen Sprints
B1: Casos de prueba por sprint
B2: Los conteos se calculan desde las hojas CDP-Sprint. Sprint 3 en curso.
B4: Sprint | C4: Alcance | D4: HDU | E4: Casos | F4: Aprobados | G4: Con observación | H4: % aprobado
B5: Sprint 1 | C5: Épica 1: acceso, portales por rol y organización QA | D5: 24 | E5: =COUNTA('CDP-Sprint 1'!B5:B76) -> 72 | F5: =COUNTIF('CDP-Sprint 1'!L5:L76,"Aprobado") -> 71 | G5: =COUNTIF('CDP-Sprint 1'!L5:L76,"Aprobado con observación") -> 1 | H5: =IF(E5=0,0,(F5+G5)/E5) -> 1
B6: Sprint 2 | C6: Épica 2: gestión de historias de usuario (HDU) | D6: 8 | E6: =COUNTA('CDP-Sprint 2'!B5:B28) -> 24 | F6: =COUNTIF('CDP-Sprint 2'!L5:L28,"Aprobado") -> 24 | G6: =COUNTIF('CDP-Sprint 2'!L5:L28,"Aprobado con observación") -> 0 | H6: =IF(E6=0,0,(F6+G6)/E6) -> 1
B7: Sprint 3 (actual) | C7: Épica 3: certificación y entregables, más el rediseño del inicio de sesión y la recuperación de contraseña (E1-F13, E1-B13) | D7: 10 | E7: =COUNTA('CDP-Sprint 3'!B5:B38) -> 34 | F7: =COUNTIF('CDP-Sprint 3'!L5:L38,"Aprobado") -> 33 | G7: =COUNTIF('CDP-Sprint 3'!L5:L38,"Aprobado con observación") -> 1 | H7: =IF(E7=0,0,(F7+G7)/E7) -> 1
B8: Total | D8: =SUM(D5:D7) -> 42 | E8: =SUM(E5:E7) -> 130 | F8: =SUM(F5:F7) -> 128 | G8: =SUM(G5:G7) -> 2 | H8: =IF(E8=0,0,(F8+G8)/E8) -> 1
